<mujoco model="mirobot">
  <compiler angle="radian" meshdir="Mirobot-STL" autolimits="true" />
  <!-- <option cone="elliptic" impratio="10"/> -->

  <default class="main">

    <!-- <equality solref="${error_timestep} 1" /> -->
    <!-- <geom solref="${error_timestep} 1" contype="${2**world_congroup}"
    conaffinity="${2**world_congroup}"/> -->
    <geom contype="1" conaffinity="1" />

    <!-- <default class="tcp_compliance">
      <equality solref="${compliance_timestep} 1" />
      </default> -->

    <default class="WL-MiroPRO-6R200-05MM">
      <geom contype="2" conaffinity="1" />

      <default class="visual">
        <geom type="mesh" contype="0" conaffinity="0" group="2" />
      </default>

      <default class="collision">
        <geom type="mesh" contype="1" conaffinity="1" group="3" />
      </default>

      <default class="Joint1">
        <joint pos="0 0 0" axis="0 0 1" range="-1.919 2.792" damping="7.86" />
        <position ctrlrange="-1.919 2.792" kp="30" />
      </default>
      <default class="Joint2">
        <joint pos="0 0 0" axis="0 0 1" range="-0.611 1.222" damping="9.86" />
        <!-- <joint pos="0 0 0" axis="0 0 1" range="-0.031 1.802" damping="2.86"/> -->
        <position ctrlrange="-0.611 1.222" kp="30" />
      </default>
      <default class="Joint3">
        <!-- <joint pos="0 0 0" axis="0 0 1 " range="-2.094 1.047" damping="2.86"/> -->
        <joint pos="0 0 0" axis="0 0 1 " range="-1.565 1.40" damping="8.586" />
        <position ctrlrange="-1.565 1.40" kp="25" />
      </default>
      <default class="Joint4">
        <joint pos="0 0 0" axis="0 0 1" range="-3.142 3.142" damping="1.286" />
        <position ctrlrange="-3.142 3.142" kp="20" />
      </default>
      <default class="Joint5">
        <!-- <joint pos="0 0 0" axis="0 0 -1" range="-3.49 0.523" damping="2.86"/> -->
        <joint pos="0 0 0" axis="0 0 -1" range="-1.8 2.2" damping="1.286" />
        <position ctrlrange="-1.8 2.2" kp="10" />
      </default>
      <default class="Robot2:Joint1">
        <joint pos="0 0 0" axis="0 0 1" range="-10 10" damping="25.0" />
        <position ctrlrange="-10 10" kp="30" />
      </default>
      <default class="Robot2:Joint2">
        <joint pos="0 0 0" axis="0 0 1" range="-0.611 1.222" damping="25.0" />
        <!-- <joint pos="0 0 0" axis="0 0 1" range="-0.031 1.802" damping="2.86"/> -->
        <position ctrlrange="-0.611 1.222" kp="10" />
      </default>
      <default class="Robot2:Joint3">
        <!-- <joint pos="0 0 0" axis="0 0 1 " range="-2.094 1.047" damping="2.86"/> -->
        <joint pos="0 0 0" axis="0 0 1 " range="-1.565 1.40" damping="25.0" />
        <position ctrlrange="-1.565 1.40" kp="10" />
      </default>
      <default class="Robot2:Joint4">
        <joint pos="0 0 0" axis="0 0 1" range="-3.142 3.142" damping="10.0" />
        <position ctrlrange="-3.142 3.142" kp="10" />
      </default>
      <default class="Robot2:Joint5">
        <!-- <joint pos="0 0 0" axis="0 0 -1" range="-3.49 0.523" damping="2.86"/> -->
        <joint pos="0 0 0" axis="0 0 -1" range="-1.8 2.2" damping="10.0" />
        <position ctrlrange="-1.8 2.2" kp="5" />
      </default>
      <!-- <default class="Joint6">
        <joint pos="0 0 0" axis="0 0 1" range="-6.283 6.283" damping="0.286" />
        <position ctrlrange="-6.283 6.283" kp="1" />
      </default> -->
    </default>
    <!-- <default class="endeffector">
      <geom contype="4" conaffinity="1" />
    </default> -->
    <default class="acker_solver_param">
      <!--solver
      impedance and reference(?) for ackerman equality constraint-->
      <!--default
      solimp: "0.900 0.950 0.001"-->
      <!--default
      solref: "0.020 1.000"-->
      <!--solref:
      (timeconst, dampratio)
			b = 2 / (dmax * timeconst)
			k = d(r) / (dmax * dmax * timeconst * timeconst * dampratio * dampratio)
		-->
      <equality solimp="0.9950 0.9990 0.0001" solref="0.0100 0.7500" />
    </default>

    <default class="active_adhesion">
      <!-- <geom rgba=".8 .5 .5 1" margin=".01" gap=".01"/> -->
      <geom margin=".01" gap=".01"/>
    </default>

  </default>

  <asset>
    <material name="MatWheel" specular="1" rgba=".1 .1 .1 1" />
    <material name="MatBody" specular="1" rgba=".6 .6 .1 1" />
    
    <!-- blue -->
    <material name="MatBody_2" specular="1" rgba="0.2 0.2 1.0 1" /> 

    <!-- grey -->
    <material name="MatBody_3" specular="1" rgba="0.8 0.8 0.8 1" />
    <mesh name="chasis" scale=".01 .006 .0015"
      vertex=" 9   2   0
              -10  10  10
               9  -2   0
               10  3  -10
               10 -3  -10
              -8   10 -10
              -10 -10  10
              -8  -10 -10
              -5   0   20" />
    <material name="robot_mat" rgba="0.4 0.4 0.9 1" />
    <material name="metal" rgba="0.58 0.58 0.58 1" />
    <material name="silicone" rgba="0.1882 0.1882 0.1882 1" />
    <material name="gray" rgba="0.4627 0.4627 0.4627 1" />
    <material name="black" rgba="0.149 0.149 0.149 1" />

    <mesh name="base_link" file="base_link.stl" />
    <mesh name="link1" file="Link1.stl" />
    <mesh name="link2" file="Link2.stl" />
    <mesh name="link3" file="Link3.stl" />
    <mesh name="link4" file="Link4.stl" />
    <mesh name="link5" file="Link5.stl" />
    <mesh name="link6" file="Link6.stl" />
    <mesh name="ForkLift" file="ForkLift.stl" scale="0.0008 0.0008 0.001" />
  </asset>

  <!-- <default>
      <default class="mirobot">
          <mesh scale="0.001 0.001 0.001"/>
          <general biastype="affine"/>
      </default>
  </default> -->

  <statistic meansize="0.0683645" extent="0.410433" center="0.170127 0.0599294 0.136871" />


  <worldbody>
    <body name="robot1:rover" pos="-6 0 0.2" >
    <!-- <body name="robot1:rover" pos="2.5 0 0.2" > -->

      <light name="robot1:lamp" active="true" directional="true" cutoff="4" exponent="20"
        diffuse="1 1 1"
        specular="0 0 0" pos="0 0 2.5" dir="0 0 -1 " />

      <!-- <camera name="first-person" mode="fixed" pos=".22 0 .08" euler="180 -133 -90" fovy="90"/> -->

      <joint name="robot1:centroid" type="free" pos="0 0 0" />
      <geom name="robot1:rover-body" type="box" pos="0 0 -0.1" size="0.15 0.11 0.044" mass="40"
        material="MatBody" />
      <geom class="collision" type="box" pos="0 0 -0.1" size="0.15 0.11 0.044" />
      <!-- <site type="box" size=".01 .07 .07" pos=".2 0 0"/> -->
      <body name="robot1:r-l-wheel" pos="-0.1 0.12 -0.15">
        <joint name="robot1:r-l-drive-hinge" type="hinge" pos="0 0 0" axis="0 1 0" damping="1.01" />
        <geom type="cylinder" size=".05" fromto="0 0 0 0 0.05 0" mass=".125" material="MatWheel"
          condim="4" />
        <site size=".01" pos="0 .05 .03" />
        <site size=".01" pos="0 .05 -.03" />
        <site size=".01" pos="0 0 .03" />
        <site size=".01" pos="0 0 -.03" />
      </body>
      <body name="robot1:r-r-wheel" pos="-0.1 -0.12 -0.15">
        <joint name="robot1:r-r-drive-hinge" type="hinge" pos="0 0 0" axis="0 1 0" damping="1.01" />
        <geom type="cylinder" size=".05" fromto="0 0 0 0 -0.05 0" mass=".125" material="MatWheel"
          condim="4" />
        <site size=".01" pos="0 -.05 .03" />
        <site size=".01" pos="0 -.05 -.03" />
        <site size=".01" pos="0 0 .03" />
        <site size=".01" pos="0 0 -.03" />
      </body>
      <body name="robot1:ghost-steer-wheel" pos="0 0 -0.1">
        <joint name="robot1:ghost-steer-hinge" type="hinge" pos="0 0 0" axis="0 0 1" limited="true"
          range="-17 17" damping="0" />
        <geom type="cylinder" size=".01 .01" axisangle="1 0 0 90" contype="2" conaffinity="2"
          mass="0.002" />
      </body>
      <body name="robot1:f-l-wheel" pos=".1 0.15 -.15">
        <geom type="capsule" size=".005" fromto="0 0 0 0 0 .08" contype="2" conaffinity="2" />
        <joint name="robot1:f-l-steer-hinge" type="hinge" pos="0 0 0" axis="0 0 1" damping="0.01"
          limited="true" range="-40 40" />
        <body name="robot1:f-l-steer-assembly">
          <geom type="cylinder" size=".01" fromto="0 -.015 0 0 0.015 0" mass=".125"
        material="MatWheel" />
          <body name="robot1:f-l-wheel-1">
        <joint name="robot1:f-l-drive-hinge-1" type="hinge" pos="0 0 0" axis="0 1 0"
          damping="0.01" />
        <geom type="cylinder" size=".05" fromto="0 -.015 0 0 -0.010 0" mass=".125"
          material="MatWheel" condim="4" />
        <site size=".01" pos="0 -0.0125  0.03" />
        <site size=".01" pos="0 -0.0125 -0.03" />
          </body>
          <body name="robot1:f-l-wheel-2">
        <joint name="robot1:f-l-drive-hinge-2" type="hinge" pos="0 0 0" axis="0 1 0"
          damping="0.01" />
        <geom type="cylinder" size=".05" fromto="0 .010 0 0 0.015 0" mass=".125"
          material="MatWheel" condim="4" />
        <site size=".01" pos="0  0.0125  0.03" />
        <site size=".01" pos="0  0.0125 -0.03" />
          </body>
        </body>
      </body>
      <body name="robot1:f-r-wheel" pos=".1 -0.15 -.15">
        <geom type="capsule" size=".005" fromto="0 0 0 0 0 .08" contype="2" conaffinity="2" />
        <joint name="robot1:f-r-steer-hinge" type="hinge" pos="0 0 0" axis="0 0 1" damping="0.01"
          limited="true" range="-40 40" />


        <body name="robot1:f-r-steer-assembly">
          <geom type="cylinder" size=".01" fromto="0 -.015 0 0 0.015 0" mass=".125"
        material="MatWheel" />
          <body name="robot1:f-r-wheel-1">
        <joint name="robot1:f-l-drive-hinge-3" type="hinge" pos="0 0 0" axis="0 1 0"
          damping="0.01" />
        <geom type="cylinder" size=".05" fromto="0 -.015 0 0 -0.010 0" mass=".125"
          material="MatWheel" condim="4" />
        <site size=".01" pos="0 -0.0125  0.03" />
        <site size=".01" pos="0 -0.0125 -0.03" />
          </body>
          <body name="robot1:f-r-wheel-2">
        <joint name="robot1:f-l-drive-hinge-4" type="hinge" pos="0 0 0" axis="0 1 0"
          damping="0.01" />
        <geom type="cylinder" size=".05" fromto="0 .010 0 0 0.015 0" mass=".125"
          material="MatWheel" condim="4" />
        <site size=".01" pos="0  0.0125  0.03" />
        <site size=".01" pos="0  0.0125 -0.03" />
          </body>
        </body>
      </body>

      <!-- ROBOT ARM -->
      <body name="robot1:base" pos="0.05 0 -0.105" childclass="WL-MiroPRO-6R200-05MM">
        <body name="robot1:base_link" pos="0 0 0">
          <inertial pos="0 0 0.0295631" quat="0.5 0.5 -0.5 0.5" mass="0.1"
            diaginertia="0.00181346 0.00122515 0.00122515" />
          <geom class="visual" type="mesh" rgba="0.478431 0.478431 0.478431 1" mesh="base_link" />
          <geom class="collision" mesh="base_link" />

          <body name="robot1:link1" pos="0 0 0.0657039">
            <inertial pos="0.0139205 0.000175676 0.0278205"
              quat="0.63697 0.301503 0.306394 0.639912"
              mass="0.100784" diaginertia="6.20698e-05 5.14973e-05 2.49373e-05" />
            <joint name="robot1:Joint1" class="Joint1" />
            <geom class="visual" type="mesh" rgba="0.792157 0.819608 0.933333 1" mesh="link1" />
            <geom class="collision" mesh="link1" />

            <!-- quat="0.500 -0.500 -0.500 -0.500" -->
            <body name="robot1:link2" pos="0.02967 -0.0219 0.0616"
              quat="0.354 -0.354 -0.612 -0.612">
              <inertial pos="-0.000285886 -0.0166553 0.0497577"
                quat="0.707123 -0.0011095 -0.00125416 0.707089"
                mass="0.132171"
                diaginertia="0.000225757 0.000214472 2.33029e-05" />
              <joint name="robot1:Joint2" class="Joint2" />
              <geom class="visual" type="mesh" rgba="1 0.6 0.247059 1" mesh="link2" />
              <geom class="collision" mesh="link2" />

              <body name="robot1:link3" pos="0.108 0 -0.0098">
                <inertial pos="0.0158955 0.0218157 0.00468223"
                  quat="0.0042885 0.613846 -0.00270477 0.78941" mass="0.0999859"
                  diaginertia="0.000128775 0.000119394 2.89671e-05" />
                <joint name="robot1:Joint3" class="Joint3" />
                <geom class="visual" type="mesh" rgba="0.792157 0.819608 0.933333 1" mesh="link3" />
                <geom class="collision" mesh="link3" />

                <!-- quat="1 0 0 0" -->
                <body name="robot1:link4" pos="0.021295 0.1075 0.0312" quat="0.707 -0.707 0 0">
                  <inertial pos="0.0397448 -3.52691e-07 8.51159e-07"
                    quat="-1.72755e-05 0.70712 1.30532e-05 0.707094" mass="0.0455777"
                    diaginertia="2.34679e-05 1.74414e-05 1.02362e-05" />
                  <joint name="robot1:Joint4" class="Joint4" />
                  <geom class="visual" type="mesh" rgba="1 0.6 0.247059 1" mesh="link4" />
                  <geom class="collision" mesh="link4" />

                  <body name="robot1:link5" pos="0.00 -0.011 0.0615" quat="0.707 -0.707 0 0">
                    <inertial pos="0 0.006295 0.00755281" quat="1 1.17491e-05 0 0" mass="0.0143828"
                      diaginertia="1.94302e-06 1.83053e-06 1.09304e-06" />
                    <joint name="robot1:Joint5" class="Joint5" />
                    <geom class="visual" type="mesh" rgba="0.792157 0.819608 0.933333 1"
                      mesh="link5" />
                    <geom class="collision" mesh="link5" />


                    <!-- <body name="robot1:link6" pos="0.0 -0.007 0.0005" quat="0 -0.707 0 -0.707">
                      <geom class="visual" type="mesh" size="0.001 0.001" mass="0.001"
                        mesh="ForkLift" />
                      <geom class="collision" mesh="ForkLift" friction="5 5 5"
                        solimp="0.99 0.99 0.001" solref="0.02 1" /> -->

                    <body name="robot1:link6" pos="0 -0.0165 0.0105" quat="0.707 -0.707 0 0" gravcomp="1">
                    <!-- <joint name="robot1:Joint6" class="Joint6" /> -->
                      <!-- <inertial pos="0 0.006295 0.00755281" quat="1 1.17491e-05 0 0" mass="0.01"
                        diaginertia="1.94302e-06 1.83053e-06 1.09304e-06" />   -->
                      <geom type="mesh" size="0.001 0.002" mass="0.0001" mesh="link6" friction="3 0.01 0.001" solimp="0.99 0.99 0.001" solref="0.02 1"/>
                      <geom class="collision" mesh="link6" />
                      <body name="robot1:vacuum_sphere" pos="0 0 -0.028" childclass="active_adhesion">

                        <site name="robot1:vacuum_contact_site" pos="0 0 0" size="0.01"/>

                        <geom type="sphere" size="0.002" rgba="0.8 0.2 0.2 1" friction="3 0.01 0.001" solimp="0.99 0.99 0.001" solref="0.02 1"/>
                        <geom type="sphere" size="0.002" rgba="0.8 0.2 0.2 1" pos="0.0027 0.0027 0" friction="3 0.01 0.001" solimp="0.99 0.99 0.001" solref="0.02 1"/>
                        <geom type="sphere" size="0.002" rgba="0.8 0.2 0.2 1" pos="0.0027 -.0027 0" friction="3 0.01 0.001" solimp="0.99 0.99 0.001" solref="0.02 1"/>
                        <geom type="sphere" size="0.002" rgba="0.8 0.2 0.2 1" pos="-.0027 0.0027 0" friction="3 0.01 0.001" solimp="0.99 0.99 0.001" solref="0.02 1"/>
                        <geom type="sphere" size="0.002" rgba="0.8 0.2 0.2 1" pos="-.0027 -.0027 0" friction="3 0.01 0.001" solimp="0.99 0.99 0.001" solref="0.02 1"/>
                        <geom type="sphere" size="0.002" rgba="0.8 0.2 0.2 1" pos="-.003 0 0" friction="3 0.01 0.001" solimp="0.99 0.99 0.001" solref="0.02 1"/>
                        <geom type="sphere" size="0.002" rgba="0.8 0.2 0.2 1" pos=".003 0 0" friction="3 0.01 0.001" solimp="0.99 0.99 0.001" solref="0.02 1"/>
                        <geom type="sphere" size="0.002" rgba="0.8 0.2 0.2 1" pos="0 -.003 0" friction="3 0.01 0.001" solimp="0.99 0.99 0.001" solref="0.02 1"/>
                        <geom type="sphere" size="0.002" rgba="0.8 0.2 0.2 1" pos="0 .003 0" friction="3 0.01 0.001" solimp="0.99 0.99 0.001" solref="0.02 1"/>
                      </body>
                      <!-- <body name="4boxes" pos=".12 0 -.08" childclass="active_adhesion">
                        <site name="force_sensor" group="3"/>
                        <joint name="arm3" damping=".01" pos="0 -.03 0"/>
                        <geom size=".015 .015 .01" pos="0.015 0.015 0"/>
                        <geom size=".015 .015 .01" pos="0.015 -.015 0"/>
                        <geom size=".015 .015 .01" pos="-.015 0.015 0"/>
                        <geom size=".015 .015 .01" pos="-.015 -.015 0"/>
                      </body> -->

                    </body>
                  </body>
                </body>
              </body>
            </body>
          </body>
        </body>
      </body>
    </body>
    <!-- END-EFFECTOR -->
    <!-- <body name="link6_mocap" mocap="true" />
    <body name="link6_dummy" childclass="endeffector">
      <freejoint />
      <body name="link6_compliant" gravcomp="0">
        <inertial pos="0.0204857 -3.59449e-07 -0.0175089" quat="0.479509 0.519656 0.52003 0.479164"
          mass="0.0381324" diaginertia="2.62395e-05 2.61171e-05 3.3979e-06" />
        <geom quat="1.76037e-12 1.32679e-06 1 1.32679e-06" type="mesh" rgba="1 1 1 1" mesh="link6" />
        <site name="ft_sensorsite" />

        <body name="link61" pos="-0.046 0 -0.016"
          quat="-2.59734e-06 0.707105 -2.59735e-06 -0.707108">
          <inertial pos="0.005 1.36612e-07 -0.106942" quat="0.5 0.5 -0.5 0.5" mass="0.112187"
            diaginertia="1.55382e-05 1.05678e-05 1.05678e-05" />
          <geom type="mesh" rgba="1 1 1 1" mesh="link6" />

          <body name="imu_frame" pos="0 0 -0.11">
            <site name="imu_sensorsite" />
          </body>
        </body>
      </body>
    </body> -->

    <!-- MISC -->
    <light pos="0 0 1000" castshadow="true" />
  </worldbody>


  <tendon>
    <fixed name="robot1:rear-differential">
      <joint joint="robot1:r-l-drive-hinge" coef="1" />
      <joint joint="robot1:r-r-drive-hinge" coef="1" />
    </fixed>
  </tendon>

  <equality>
    <joint name="robot1:f-l-steer-hinge" joint1="robot1:f-l-steer-hinge"
      joint2="robot1:ghost-steer-hinge"
      polycoef="0.000093610018132620019 2.0041497325730204 1.4716131190668178 -1.0929725380842041 -3.2252012765547819"
      class="acker_solver_param" />
    <joint name="robot1:f-r-steer-hinge" joint1="robot1:f-r-steer-hinge"
      joint2="robot1:ghost-steer-hinge"
      polycoef="-0.00017013070152971507 2.0039379507086514 -1.4684576386267671 -1.0901354124362155 3.1974185558159771"
      class="acker_solver_param" />
  </equality>

  <sensor>
    <touch name="robot1:vacuum_touch" site="robot1:vacuum_contact_site"/>
  </sensor>

</mujoco>