<mujoco model="mirobot">
  <compiler angle="radian" meshdir="Mirobot-STL-master" autolimits="true" />
  <!-- <option cone="elliptic" impratio="10"/> -->

  <default class="main">

    <!-- <equality solref="${error_timestep} 1" /> -->
    <!-- <geom solref="${error_timestep} 1" contype="${2**world_congroup}"
    conaffinity="${2**world_congroup}"/> -->
    <geom contype="1" conaffinity="1" />

    <!-- <default class="tcp_compliance">
      <equality solref="${compliance_timestep} 1" />
      </default> -->

    <default class="WL-MiroPRO-6R200-05MM">
      <geom contype="2" conaffinity="1" />
      <default class="Joint1"> 
        <joint pos="0 0 0" axis="0 0 1" range="-1.919 2.792" damping="70.86"/>
        <position ctrlrange="-1.919 2.792" kp="300"/>
      </default>
      <default class="Joint2">
        <joint pos="0 0 0" axis="0 0 1" range="-0.611 1.222" damping="90.86"/>
        <!-- <joint pos="0 0 0" axis="0 0 1" range="-0.031 1.802" damping="2.86"/> -->
        <position ctrlrange="-0.611 1.222" kp="300"/>
      </default>
      <default class="Joint3">
        <!-- <joint pos="0 0 0" axis="0 0 1 " range="-2.094 1.047" damping="2.86"/> -->
        <joint pos="0 0 0" axis="0 0 1 " range="-1.565 1.40" damping="85.86"/>
        <position ctrlrange="-1.565 1.40" kp="250"/>
      </default>
      <default class="Joint4">
        <joint pos="0 0 0" axis="0 0 1" range="-3.142 3.142" damping="12.86"/>
        <position ctrlrange="-3.142 3.142" kp="200"/>
      </default>
      <default class="Joint5">
        <!-- <joint pos="0 0 0" axis="0 0 -1" range="-3.49 0.523" damping="2.86"/> -->
         <joint pos="0 0 0" axis="0 0 -1" range="-1.8 2.2" damping="12.86"/>
        <position ctrlrange="-1.8 2.2" kp="100"/>
      </default>
      <default class="Joint6">
        <joint pos="0 0 0" axis="0 0 1" range="-6.283 6.283" damping="2.86"/>
        <position ctrlrange="-6.283 6.283" kp="50"/>
      </default>
    </default>
    <!-- <default class="endeffector">
      <geom contype="4" conaffinity="1" />
    </default> -->

  </default>

  <asset>
    <mesh name="base_link" file="base_link.STL" />
    <mesh name="link1" file="Link1.stl" />
    <mesh name="link2" file="Link2.stl" />
    <mesh name="link3" file="Link3.stl" />
    <mesh name="link4" file="Link4.stl" />
    <mesh name="link5" file="Link5.stl" />
    <mesh name="link6" file="Link6.stl" />
  </asset>

  <!-- <default>
      <default class="mirobot">
          <mesh scale="0.001 0.001 0.001"/>
          <general biastype="affine"/>
      </default>
  </default> -->

  <statistic meansize="0.0683645" extent="0.410433" center="0.170127 0.0599294 0.136871" />


  <worldbody>
    <!-- ROBOT ARM -->
    <body name="base" pos="0 0 0" childclass="WL-MiroPRO-6R200-05MM">
      <body name="base_link" pos="0 0 0" >
        <inertial pos="0 0 0.0295631" quat="0.5 0.5 -0.5 0.5" mass="0.83046"
          diaginertia="0.00181346 0.00122515 0.00122515" />
        <geom type="mesh" rgba="0.478431 0.478431 0.478431 1" mesh="base_link" />

        <body name="link1" pos="0 0 0.0657039" >
          <inertial pos="0.0139205 0.000175676 0.0278205" quat="0.63697 0.301503 0.306394 0.639912"
            mass="0.100784" diaginertia="6.20698e-05 5.14973e-05 2.49373e-05" />
          <joint name="Joint1" class = "Joint1" />
          <geom type="mesh" rgba="0.792157 0.819608 0.933333 1" mesh="link1" />


          <!-- quat="0.500 -0.500 -0.500 -0.500" -->
          <body name="link2" pos="0.02967 -0.0219 0.0616" 
            quat="0.354 -0.354 -0.612 -0.612">
            <inertial pos="-0.000285886 -0.0166553 0.0497577"
              quat="0.707123 -0.0011095 -0.00125416 0.707089"
              mass="0.132171"
              diaginertia="0.000225757 0.000214472 2.33029e-05" />
            <joint name="Joint2" class="Joint2" />
            <geom type="mesh" rgba="1 0.6 0.247059 1" mesh="link2" />

            <body name="link3" pos="0.108 0 -0.0098" >
              <inertial pos="0.0158955 0.0218157 0.00468223"
                quat="0.0042885 0.613846 -0.00270477 0.78941" mass="0.0999859"
                diaginertia="0.000128775 0.000119394 2.89671e-05" />
              <joint name="Joint3" class="Joint3" />
              <geom type="mesh" rgba="0.792157 0.819608 0.933333 1" mesh="link3" />
              
              <!-- quat="1 0 0 0" -->
              <body name="link4" pos="0.021295 0.1075 0.0312"  quat="0.707 -0.707 0 0">
                <inertial pos="0.0397448 -3.52691e-07 8.51159e-07"
                  quat="-1.72755e-05 0.70712 1.30532e-05 0.707094" mass="0.0455777"
                  diaginertia="2.34679e-05 1.74414e-05 1.02362e-05" />
                <joint name="Joint4" class="Joint4" />
                <geom type="mesh" rgba="1 0.6 0.247059 1" mesh="link4" />

                <body name="link5" pos="0.00 -0.011 0.0615"  quat="0.707 -0.707 0 0">
                  <inertial pos="0 0.006295 0.00755281" quat="1 1.17491e-05 0 0" mass="0.0143828"
                    diaginertia="1.94302e-06 1.83053e-06 1.09304e-06" />
                  <joint name="Joint5" class="Joint5" />
                  <geom type="mesh" rgba="0.792157 0.819608 0.933333 1" mesh="link5" />


                  <body name="link6" pos="0.0 -0.01665 0.0105" quat="0.707 -0.707 0 0">
                    <joint name="Joint6" class="Joint6" />
                    <geom type="mesh" size="0.001 0.001" mass="0.001" mesh="link6"/>

                  </body>
                </body>
              </body>
            </body>
          </body>
        </body>
      </body>
    </body>

    <!-- END-EFFECTOR -->
    <!-- <body name="link6_mocap" mocap="true" />
    <body name="link6_dummy" childclass="endeffector">
      <freejoint />
      <body name="link6_compliant" gravcomp="0">
        <inertial pos="0.0204857 -3.59449e-07 -0.0175089" quat="0.479509 0.519656 0.52003 0.479164"
          mass="0.0381324" diaginertia="2.62395e-05 2.61171e-05 3.3979e-06" />
        <geom quat="1.76037e-12 1.32679e-06 1 1.32679e-06" type="mesh" rgba="1 1 1 1" mesh="link6" />
        <site name="ft_sensorsite" />

        <body name="link61" pos="-0.046 0 -0.016"
          quat="-2.59734e-06 0.707105 -2.59735e-06 -0.707108">
          <inertial pos="0.005 1.36612e-07 -0.106942" quat="0.5 0.5 -0.5 0.5" mass="0.112187"
            diaginertia="1.55382e-05 1.05678e-05 1.05678e-05" />
          <geom type="mesh" rgba="1 1 1 1" mesh="link6" />

          <body name="imu_frame" pos="0 0 -0.11">
            <site name="imu_sensorsite" />
          </body>
        </body>
      </body>
    </body> -->

    <!-- MISC -->
    <light pos="0 0 1000" castshadow="true" />
  </worldbody>

  <!-- <equality>
    <weld body1="link6_mocap" body2="link6_dummy" class="tcp_compliance" relpose="0 0 0 0 0 0 0"/>
  </equality> -->

  <!-- SENSORS -->
  <!-- <sensor>
    <force name="force" site="ft_sensorsite" />
    <torque name="torque" site="ft_sensorsite" />

    <framequat name="quat" objtype="site" objname="imu_sensorsite" />
    <gyro name="angvel" site="imu_sensorsite" />
    <accelerometer name="linacc" site="imu_sensorsite" />
  </sensor> -->

  <!-- Define a grouping of sensors that correspond to geometry_msgs/Wrench -->
  <!-- <custom>
    <tuple name="wrench">
      <element objname="wrench_sensor" objtype="tuple" />
    </tuple>

    <tuple name="wrench_sensor">
      <element objname="force" objtype="sensor" />
      <element objname="torque" objtype="sensor" />
    </tuple>
  </custom> -->

  <!-- Define a grouping of sensors that correspond to sensor_msgs/Imu -->
  <!-- <custom>
    <tuple name="imu">
      <element objname="imu_sensor" objtype="tuple" />
    </tuple>

    <tuple name="imu_sensor">
      <element objname="quat" objtype="sensor" />
      <element objname="angvel" objtype="sensor" />
      <element objname="linacc" objtype="sensor" />
    </tuple>
  </custom> -->

  <actuator>
    <position class="Joint1" name="Joint1" joint="Joint1"/>
    <position class="Joint2" name="Joint2" joint="Joint2"/>
    <position class="Joint3" name="Joint3" joint="Joint3"/>
    <position class="Joint4" name="Joint4" joint="Joint4"/>
    <position class="Joint5" name="Joint5" joint="Joint5"/>
    <position class="Joint6" name="Joint6" joint="Joint6"/>
  </actuator>

</mujoco>